Workbook

Sheet 1_Annahmen
A1: SKIPILY – Marktannahmen & Modellparameter (gelbe Zellen = Inputs)
A3: Markt
A4: Adressierbare Bootseigner DACH | B4: 500000 | C4: BVWW / ADAC
A5: Adressierbare Bootseigner EU+UK | B5: 6000000 | C5: ICOMIA 2023
A6: Service-Provider DACH | B6: 2600 | C6: Marinas, Werften, Sailmaker, Rigger, Chandlery
A7: Service-Provider EU | B7: 5000 | C7: ICOMIA
A8: Marktdurchdringung Ziel Jahr 5 (Privat) | B8: 0.012 | C8: 1.2% – ambitioniert
A10: User-Konversion
A11: Free → Plus Konversionsrate | B11: 0.04 | C11: Strava 4-6%, Komoot 3-5%
A12: Free → Pro Konversionsrate | B12: 0.01 | C12: Power-User
A13: Monatliche Churn Privat | B13: 0.03 | C13: saisonbedingt
A14: Monatliche Churn Provider | B14: 0.02 | C14: B2B SaaS Benchmark
A16: Akquisitionskosten (CAC)
A17: CAC Privat-User (Free) | B17: 4 | C17: Performance Marketing
A18: CAC Privat-User (Paid Conversion) | B18: 18 | C18: Blended
A19: CAC Service-Provider | B19: 240 | C19: Outbound Sales + Field
A21: Variable Pro-User-Kosten / Monat
A22: Cloud/Storage pro aktivem User (€/Monat) | B22: 0.12 | C22: Supabase + S3 + Maps
A23: Support-Kosten pro zahlendem User (€/Monat) | B23: 0.18 | C23: Tickets + Tooling
A24: App Store Gebühr Jahr 1 | B24: 0.3 | C24: Apple/Google Standard
A25: App Store Gebühr ab Jahr 2 | B25: 0.15 | C25: Apple Small Business
A26: Payment-Provider-Gebühr (%) | B26: 0.029 | C26: Stripe
A27: Shop-Provision auf vermittelte Käufe | B27: 0.1 | C27: 10%
A28: Buchungs-Provision auf Marina/Service | B28: 0.05 | C28: 5%
A30: HINWEIS: Alle gelben Zellen sind Annahmen – einfach ändern, das gesamte Modell rechnet automatisch nach.

Sheet 2_Pricing
A1: PRICING-STRATEGIE: Privat-User & Service-Provider
A3: Privat-User (B2C, Freemium)
A4: Tier | B4: Preis/Monat | C4: Preis/Jahr | D4: Ø Blended €/Mon | E4: Zielgruppe
A5: Free | B5: 0 | C5: 0 | D5: =B5*0.6+(C5/12)*0.4 -> 0 | E5: Einsteiger / Lead-Gen
A6: Skipily Plus | B6: 4.99 | C6: 49 | D6: =B6*0.6+(C6/12)*0.4 -> 4.6273333 | E6: Hobby-Skipper, 1-2 Boote
A7: Skipily Pro | B7: 9.99 | C7: 99 | D7: =B7*0.6+(C7/12)*0.4 -> 9.294 | E7: Eigner-Profis, Mehrboot, Charterer
A9: Service-Provider (B2B SaaS + Provisionen)
A10: Tier | B10: Preis/Monat | C10: Preis/Jahr | D10: Ø Blended €/Mon | E10: Inhalte
A11: Basic Listing | B11: 0 | C11: 0 | D11: =B11*0.5+(C11/12)*0.5 -> 0 | E11: Verifiziertes Profil, Map-Pin (Lead-Gen)
A12: Provider Starter | B12: 0 | C12: 0 | D12: =B12*0.5+(C12/12)*0.5 -> 0 | E12: Foto-Galerie, 5 Promos/Mon, Reviews
A13: Provider Pro | B13: 79 | C13: 790 | D13: =B13*0.5+(C13/12)*0.5 -> 72.416667 | E13: Unlimited Promos, Shop, Analytics, Top-Placement
A14: Provider Enterprise | B14: 199 | C14: 1990 | D14: =B14*0.5+(C14/12)*0.5 -> 182.41667 | E14: Multi-Location, API, White-Label-Widget
A17: Mix-Annahmen (für Umsatzprognose – änderbar)
A18: Anteil zahlende Privat → Plus | B18: 0.8
A19: Anteil zahlende Privat → Pro | B19: 0.2
A20: Anteil Provider → Starter | B20: 0.55
A21: Anteil Provider → Pro | B21: 0.35
A22: Anteil Provider → Enterprise | B22: 0.1
A24: ARPU/Monat zahlender Privat-User | B24: =D6*B18+D7*B19 -> 5.5606667
A25: ARPU/Monat zahlender Provider | B25: =D12*B20+D13*B21+D14*B22 -> 43.5875

Sheet 3_Investment
A1: INVESTMENT-PLAN (Kapitalbedarf Seed → Series A)
A3: Position / Phase | B3: Jahr 1 | C3: Jahr 2 | D3: Jahr 3 | E3: Jahr 4 | F3: Jahr 5
A4: Phase | B4: MVP & Launch | C4: Scale DACH | D4: EU-Rollout | E4: Konsolidierung | F4: Profit
A5: Produktentwicklung (iOS, Backend, Web) | B5: 0 | C5: 0 | D5: 380000 | E5: 420000 | F5: 380000
A6: Design & UX | B6: 0 | C6: 0 | D6: 70000 | E6: 70000 | F6: 60000
A7: Cloud, Tools, Lizenzen, Software | B7: 18000 | C7: 35000 | D7: 60000 | E7: 90000 | F7: 120000
A8: Marketing & User-Akquise | B8: 10000 | C8: 30000 | D8: 350000 | E8: 420000 | F8: 350000
A9: Sales (Outbound Provider-Akquise) | B9: 25000 | C9: 90000 | D9: 160000 | E9: 200000 | F9: 180000
A10: Operations / Support | B10: 20000 | C10: 55000 | D10: 110000 | E10: 160000 | F10: 180000
A11: Legal, IP, Compliance, GDPR | B11: 22000 | C11: 18000 | D11: 25000 | E11: 28000 | F11: 25000
A12: Office, Reise, Sonstiges | B12: 15000 | C12: 22000 | D12: 35000 | E12: 40000 | F12: 40000
A13: Buffer / Contingency 10% | B13: 42500 | C13: 78000 | D13: 119000 | E13: 142800 | F13: 133500
A14: Investment p.a. (€) | B14: =SUM(B5:B13) -> 152500 | C14: =SUM(C5:C13) -> 328000 | D14: =SUM(D5:D13) -> 1309000 | E14: =SUM(E5:E13) -> 1570800 | F14: =SUM(F5:F13) -> 1468500
A15: Kumuliert (€) | B15: =B14 -> 152500 | C15: =B15+C14 -> 480500 | D15: =C15+D14 -> 1789500 | E15: =D15+E14 -> 3360300 | F15: =E15+F14 -> 4828800
A17: FINANZIERUNGS-ROUNDS (typisch)
A18: Round | B18: Zeitpunkt | C18: Volumen (€)
A19: Pre-Seed (Bootstrap + Angels) | B19: Q1 Jahr 1 | C19: 250000
A20: Seed Round | B20: Q4 Jahr 1 | C20: 1500000
A21: Series A | B21: Q2 Jahr 3 | C21: 5000000
A22: Summe Funding | C22: =SUM(C19:C21) -> 6750000

Sheet 4_Kosten
A1: FIXE & VARIABLE BETRIEBSKOSTEN (Jahr 1 – 5)
A3: Position | B3: Jahr 1 | C3: Jahr 2 | D3: Jahr 3 | E3: Jahr 4 | F3: Jahr 5
A4: FIX-KOSTEN (€/Jahr)
A5: Personal Engineering (FTE) | B5: 0 | C5: 0 | D5: 0 | E5: 0 | F5: 0
A6: Personal Sales/Marketing (FTE) | B6: 0 | C6: 0 | D6: 0 | E6: 0 | F6: 0
A7: Personal Operations/Support (FTE) | B7: 0 | C7: 0 | D7: 0 | E7: 0 | F7: 0
A8: Geschäftsführung | B8: =2000*6 -> 12000 | C8: =2000*12 -> 24000 | D8: =2000*12 -> 24000 | E8: =2000*12 -> 24000 | F8: =2000*12 -> 24000
A9: Büro, Co-Working | B9: 9000 | C9: 18000 | D9: 30000 | E9: 36000 | F9: 42000
A10: Software-Tools (Supabase, Google-API,GitHub Ent., Claude) | B10: 2000 | C10: 14000 | D10: 22000 | E10: 30000 | F10: 36000
A11: Legal, Buchhaltung, Steuerberatung | B11: 18000 | C11: 22000 | D11: 28000 | E11: 32000 | F11: 36000 | H11: =12*20+18*12+25*12 -> 756
A12: Versicherungen (D&O, Cyber) | B12: 3000 | C12: 6000 | D12: 10000 | E12: 14000 | F12: 16000
A13: Marketing-Fixum (SEO, Content, PR) | B13: 12000 | C13: 30000 | D13: 60000 | E13: 80000 | F13: 90000
A14: Σ Fix-Kosten | B14: =SUM(B5:B13) -> 56000 | C14: =SUM(C5:C13) -> 114000 | D14: =SUM(D5:D13) -> 174000 | E14: =SUM(E5:E13) -> 216000 | F14: =SUM(F5:F13) -> 244000
A16: VARIABLE KOSTEN (€/Jahr) – verlinkt aus Umsatzprognose
A17: Cloud / Hosting / Storage | B17: ='5_Umsatz_Prognose'!B26 -> 10800 | C17: ='5_Umsatz_Prognose'!C26 -> 43200 | D17: ='5_Umsatz_Prognose'!D26 -> 144000 | E17: ='5_Umsatz_Prognose'!E26 -> 691200 | F17: ='5_Umsatz_Prognose'!F26 -> 1123200
A18: Customer Support | B18: ='5_Umsatz_Prognose'!B27 -> 810 | C18: ='5_Umsatz_Prognose'!C27 -> 3240 | D18: ='5_Umsatz_Prognose'!D27 -> 10800 | E18: ='5_Umsatz_Prognose'!E27 -> 51840 | F18: ='5_Umsatz_Prognose'!F27 -> 84240
A19: App-Store-Gebühren (Apple/Google) | B19: ='5_Umsatz_Prognose'!B28 -> 3753.45 | C19: ='5_Umsatz_Prognose'!C28 -> 15013.8 | D19: ='5_Umsatz_Prognose'!D28 -> 50046 | E19: ='5_Umsatz_Prognose'!E28 -> 240220.8 | F19: ='5_Umsatz_Prognose'!F28 -> 390358.8
A20: Payment-Provider-Gebühren | B20: ='5_Umsatz_Prognose'!B29 -> 635.39508 | C20: ='5_Umsatz_Prognose'!C29 -> 8695.1896 | D20: ='5_Umsatz_Prognose'!D29 -> 31724.826 | E20: ='5_Umsatz_Prognose'!E29 -> 121930.22 | F20: ='5_Umsatz_Prognose'!F29 -> 232568.37
A21: Performance-Marketing CAC Free | B21: ='5_Umsatz_Prognose'!B30 -> 30000 | C21: ='5_Umsatz_Prognose'!C30 -> 60000 | D21: ='5_Umsatz_Prognose'!D30 -> 280000 | E21: ='5_Umsatz_Prognose'!E30 -> 1520000 | F21: ='5_Umsatz_Prognose'!F30 -> 1200000
A22: Aufschlag CAC Paid Conversion | B22: ='5_Umsatz_Prognose'!B31 -> 5250 | C22: ='5_Umsatz_Prognose'!C31 -> 10500 | D22: ='5_Umsatz_Prognose'!D31 -> 49000 | E22: ='5_Umsatz_Prognose'!E31 -> 266000 | F22: ='5_Umsatz_Prognose'!F31 -> 210000
A23: Sales-CAC Provider | B23: ='5_Umsatz_Prognose'!B32 -> 21600 | C23: ='5_Umsatz_Prognose'!C32 -> 112800 | D23: ='5_Umsatz_Prognose'!D32 -> 276000 | E23: ='5_Umsatz_Prognose'!E32 -> 408000 | F23: ='5_Umsatz_Prognose'!F32 -> 480000
A24: Σ Variable Kosten | B24: =SUM(B17:B23) -> 72848.845 | C24: =SUM(C17:C23) -> 253448.99 | D24: =SUM(D17:D23) -> 841570.83 | E24: =SUM(E17:E23) -> 3299191 | F24: =SUM(F17:F23) -> 3720367.2
A26: GESAMT-KOSTEN (Fix + Variabel) | B26: =B14+B24 -> 128848.85 | C26: =C14+C24 -> 367448.99 | D26: =D14+D24 -> 1015570.8 | E26: =E14+E24 -> 3515191 | F26: =F14+F24 -> 3964367.2

Sheet 5_Umsatz_Prognose (2)
A1: UMSATZPROGNOSE 2 JAHRE
A3: Kennzahl | B3: Jahr 1 | C3: Jahr 2
A4: USER-FUNNEL Privat
A5: Free MAU (Jahresende) | B5: 15000 | C5: 30000
A6: Konversion → Plus | B6: ='1_Annahmen'!B11 -> 0.04 | C6: ='1_Annahmen'!B11 -> 0.04
A7: Konversion → Pro | B7: ='1_Annahmen'!B12 -> 0.01 | C7: ='1_Annahmen'!B12 -> 0.01
A8: Zahlende User Plus | B8: =B5*B6 -> 600 | C8: =C5*C6 -> 1200
A9: Zahlende User Pro | B9: =B5*B7 -> 150 | C9: =C5*C7 -> 300
A10: Σ Zahlende Privat-User | B10: =B8+B9 -> 750 | C10: =C8+C9 -> 1500
A12: PROVIDER-FUNNEL
A13: Aktive Provider (gesamt, EOY) | B13: 180 | C13: 650
A14: Anteil zahlend (Starter+Pro+Ent) | B14: 0.3 | C14: 0.45
A15: Σ Zahlende Provider | B15: =B13*B14 -> 54 | C15: =C13*C14 -> 292.5
A17: UMSATZ-STRÖME (€/Jahr)
A18: Abo-Umsatz Privat | B18: =B10*'2_Pricing'!B24*12/2 -> 25023 | C18: =C10*'2_Pricing'!B24*12 -> 100092
A19: Abo-Umsatz Provider | B19: =B15*'2_Pricing'!B25*12/2 -> 14122.35 | C19: =C15*'2_Pricing'!B25*12 -> 152992.12
A20: Shop-Provisionen (10%) | B20: =B10*60*0.8*'1_Annahmen'!B27/2 -> 1800 | C20: =C10*80*1.5*'1_Annahmen'!B27 -> 18000
A21: Buchungs-Provisionen (5%) | B21: =B10*20*'1_Annahmen'!B28/2 -> 375 | C21: =C10*50*'1_Annahmen'!B28 -> 3750
A22: Sponsored Placements / Ads | B22: 2500 | C22: 25000
A23: GESAMTUMSATZ | B23: =SUM(B18:B22) -> 43820.35 | C23: =SUM(C18:C22) -> 299834.12
A25: VARIABLE KOSTEN-DETAIL (€/Jahr)
A26: Cloud-Kosten | B26: =B5*'1_Annahmen'!B22*12/2 -> 10800 | C26: =C5*'1_Annahmen'!B22*12 -> 43200
A27: Support-Kosten | B27: =B10*'1_Annahmen'!B23*12/2 -> 810 | C27: =C10*'1_Annahmen'!B23*12 -> 3240
A28: App-Store-Gebühren | B28: =B18*'1_Annahmen'!B24/2 -> 3753.45 | C28: =C18*'1_Annahmen'!B25 -> 15013.8
A29: Payment-Gebühren | B29: =B23*'1_Annahmen'!B26/2 -> 635.39508 | C29: =C23*'1_Annahmen'!B26 -> 8695.1896
A30: CAC Privat (Performance-Marketing, neue Free-User × CAC Free) | B30: =B5*'1_Annahmen'!B17/2 -> 30000 | C30: =MAX(0,C5-B5)*'1_Annahmen'!B17 -> 60000
A31: CAC-Aufschlag Paid Conversion (zahlende User × Paid-CAC Aufschlag) | B31: =B10*('1_Annahmen'!B18-'1_Annahmen'!B17)/2 -> 5250 | C31: =MAX(0,C10-B10)*('1_Annahmen'!B18-'1_Annahmen'!B17) -> 10500
A32: CAC Provider (Sales) | B32: =B13*'1_Annahmen'!B19/2 -> 21600 | C32: =MAX(0,C13-B13)*'1_Annahmen'!B19 -> 112800
A33: Σ Variable Kosten | B33: =SUM(B26:B32) -> 72848.845 | C33: =SUM(C26:C32) -> 253448.99

Sheet 5_Umsatz_Prognose
A1: UMSATZPROGNOSE 5 JAHRE
A3: Kennzahl | B3: Jahr 1 | C3: Jahr 2 | D3: Jahr 3 | E3: Jahr 4 | F3: Jahr 5
A4: USER-FUNNEL Privat
A5: Free MAU (Jahresende) | B5: 15000 | C5: 30000 | D5: 100000 | E5: 480000 | F5: 780000
A6: Konversion → Plus | B6: ='1_Annahmen'!B11 -> 0.04 | C6: ='1_Annahmen'!B11 -> 0.04 | D6: ='1_Annahmen'!B11 -> 0.04 | E6: ='1_Annahmen'!B11 -> 0.04 | F6: ='1_Annahmen'!B11 -> 0.04
A7: Konversion → Pro | B7: ='1_Annahmen'!B12 -> 0.01 | C7: ='1_Annahmen'!B12 -> 0.01 | D7: ='1_Annahmen'!B12 -> 0.01 | E7: ='1_Annahmen'!B12 -> 0.01 | F7: ='1_Annahmen'!B12 -> 0.01
A8: Zahlende User Plus | B8: =B5*B6 -> 600 | C8: =C5*C6 -> 1200 | D8: =D5*D6 -> 4000 | E8: =E5*E6 -> 19200 | F8: =F5*F6 -> 31200
A9: Zahlende User Pro | B9: =B5*B7 -> 150 | C9: =C5*C7 -> 300 | D9: =D5*D7 -> 1000 | E9: =E5*E7 -> 4800 | F9: =F5*F7 -> 7800
A10: Σ Zahlende Privat-User | B10: =B8+B9 -> 750 | C10: =C8+C9 -> 1500 | D10: =D8+D9 -> 5000 | E10: =E8+E9 -> 24000 | F10: =F8+F9 -> 39000
A12: PROVIDER-FUNNEL
A13: Aktive Provider (gesamt, EOY) | B13: 180 | C13: 650 | D13: 1800 | E13: 3500 | F13: 5500
A14: Anteil zahlend (Starter+Pro+Ent) | B14: 0.3 | C14: 0.45 | D14: 0.55 | E14: 0.62 | F14: 0.68
A15: Σ Zahlende Provider | B15: =B13*B14 -> 54 | C15: =C13*C14 -> 292.5 | D15: =D13*D14 -> 990 | E15: =E13*E14 -> 2170 | F15: =F13*F14 -> 3740
A17: UMSATZ-STRÖME (€/Jahr)
A18: Abo-Umsatz Privat | B18: =B10*'2_Pricing'!B24*12/2 -> 25023 | C18: =C10*'2_Pricing'!B24*12 -> 100092 | D18: =D10*'2_Pricing'!B24*12 -> 333640 | E18: =E10*'2_Pricing'!B24*12 -> 1601472 | F18: =F10*'2_Pricing'!B24*12 -> 2602392
A19: Abo-Umsatz Provider | B19: =B15*'2_Pricing'!B25*12/2 -> 14122.35 | C19: =C15*'2_Pricing'!B25*12 -> 152992.12 | D19: =D15*'2_Pricing'!B25*12 -> 517819.5 | E19: =E15*'2_Pricing'!B25*12 -> 1135018.5 | F19: =F15*'2_Pricing'!B25*12 -> 1956207
A20: Shop-Provisionen (10%) | B20: =B10*60*0.8*'1_Annahmen'!B27/2 -> 1800 | C20: =C10*80*1.5*'1_Annahmen'!B27 -> 18000 | D20: =D10*100*2.5*'1_Annahmen'!B27 -> 125000 | E20: =E10*120*3.5*'1_Annahmen'!B27 -> 1008000 | F20: =F10*140*4.5*'1_Annahmen'!B27 -> 2457000
A21: Buchungs-Provisionen (5%) | B21: =B10*20*'1_Annahmen'!B28/2 -> 375 | C21: =C10*50*'1_Annahmen'!B28 -> 3750 | D21: =D10*110*'1_Annahmen'!B28 -> 27500 | E21: =E10*200*'1_Annahmen'!B28 -> 240000 | F21: =F10*320*'1_Annahmen'!B28 -> 624000
A22: Sponsored Placements / Ads | B22: 2500 | C22: 25000 | D22: 90000 | E22: 220000 | F22: 380000
A23: GESAMTUMSATZ | B23: =SUM(B18:B22) -> 43820.35 | C23: =SUM(C18:C22) -> 299834.12 | D23: =SUM(D18:D22) -> 1093959.5 | E23: =SUM(E18:E22) -> 4204490.5 | F23: =SUM(F18:F22) -> 8019599
A25: VARIABLE KOSTEN-DETAIL (€/Jahr)
A26: Cloud-Kosten | B26: =B5*'1_Annahmen'!B22*12/2 -> 10800 | C26: =C5*'1_Annahmen'!B22*12 -> 43200 | D26: =D5*'1_Annahmen'!B22*12 -> 144000 | E26: =E5*'1_Annahmen'!B22*12 -> 691200 | F26: =F5*'1_Annahmen'!B22*12 -> 1123200
A27: Support-Kosten | B27: =B10*'1_Annahmen'!B23*12/2 -> 810 | C27: =C10*'1_Annahmen'!B23*12 -> 3240 | D27: =D10*'1_Annahmen'!B23*12 -> 10800 | E27: =E10*'1_Annahmen'!B23*12 -> 51840 | F27: =F10*'1_Annahmen'!B23*12 -> 84240
A28: App-Store-Gebühren | B28: =B18*'1_Annahmen'!B24/2 -> 3753.45 | C28: =C18*'1_Annahmen'!B25 -> 15013.8 | D28: =D18*'1_Annahmen'!B25 -> 50046 | E28: =E18*'1_Annahmen'!B25 -> 240220.8 | F28: =F18*'1_Annahmen'!B25 -> 390358.8
A29: Payment-Gebühren | B29: =B23*'1_Annahmen'!B26/2 -> 635.39508 | C29: =C23*'1_Annahmen'!B26 -> 8695.1896 | D29: =D23*'1_Annahmen'!B26 -> 31724.826 | E29: =E23*'1_Annahmen'!B26 -> 121930.22 | F29: =F23*'1_Annahmen'!B26 -> 232568.37
A30: CAC Privat (Performance-Marketing, neue Free-User × CAC Free) | B30: =B5*'1_Annahmen'!B17/2 -> 30000 | C30: =MAX(0,C5-B5)*'1_Annahmen'!B17 -> 60000 | D30: =MAX(0,D5-C5)*'1_Annahmen'!B17 -> 280000 | E30: =MAX(0,E5-D5)*'1_Annahmen'!B17 -> 1520000 | F30: =MAX(0,F5-E5)*'1_Annahmen'!B17 -> 1200000
A31: CAC-Aufschlag Paid Conversion (zahlende User × Paid-CAC Aufschlag) | B31: =B10*('1_Annahmen'!B18-'1_Annahmen'!B17)/2 -> 5250 | C31: =MAX(0,C10-B10)*('1_Annahmen'!B18-'1_Annahmen'!B17) -> 10500 | D31: =MAX(0,D10-C10)*('1_Annahmen'!B18-'1_Annahmen'!B17) -> 49000 | E31: =MAX(0,E10-D10)*('1_Annahmen'!B18-'1_Annahmen'!B17) -> 266000 | F31: =MAX(0,F10-E10)*('1_Annahmen'!B18-'1_Annahmen'!B17) -> 210000
A32: CAC Provider (Sales) | B32: =B13*'1_Annahmen'!B19/2 -> 21600 | C32: =MAX(0,C13-B13)*'1_Annahmen'!B19 -> 112800 | D32: =MAX(0,D13-C13)*'1_Annahmen'!B19 -> 276000 | E32: =MAX(0,E13-D13)*'1_Annahmen'!B19 -> 408000 | F32: =MAX(0,F13-E13)*'1_Annahmen'!B19 -> 480000
A33: Σ Variable Kosten | B33: =SUM(B26:B32) -> 72848.845 | C33: =SUM(C26:C32) -> 253448.99 | D33: =SUM(D26:D32) -> 841570.83 | E33: =SUM(E26:E32) -> 3299191 | F33: =SUM(F26:F32) -> 3720367.2

Sheet 6_GuV_Breakeven
A1: GEWINN- & VERLUSTRECHNUNG + BREAKEVEN-ANALYSE
A3: Position | B3: Jahr 1 | C3: Jahr 2 | D3: Jahr 3 | E3: Jahr 4 | F3: Jahr 5
A4: Umsatz | B4: ='5_Umsatz_Prognose'!B23 -> 43820.35 | C4: ='5_Umsatz_Prognose'!C23 -> 299834.12 | D4: ='5_Umsatz_Prognose'!D23 -> 1093959.5 | E4: ='5_Umsatz_Prognose'!E23 -> 4204490.5 | F4: ='5_Umsatz_Prognose'!F23 -> 8019599
A5: (-) Variable Kosten | B5: =-'5_Umsatz_Prognose'!B33 -> -72848.845 | C5: =-'5_Umsatz_Prognose'!C33 -> -253448.99 | D5: =-'5_Umsatz_Prognose'!D33 -> -841570.83 | E5: =-'5_Umsatz_Prognose'!E33 -> -3299191 | F5: =-'5_Umsatz_Prognose'!F33 -> -3720367.2
A6: Deckungsbeitrag | B6: =B4+B5 -> -29028.495 | C6: =C4+C5 -> 46385.135 | D6: =D4+D5 -> 252388.67 | E6: =E4+E5 -> 905299.48 | F6: =F4+F5 -> 4299231.8
A7: DB-Marge | B7: =IFERROR(B6/B4,0) -> -0.66244325 | C7: =IFERROR(C6/C4,0) -> 0.15470266 | D7: =IFERROR(D6/D4,0) -> 0.23071117 | E7: =IFERROR(E6/E4,0) -> 0.21531728 | F7: =IFERROR(F6/F4,0) -> 0.53609062
A8: (-) Fixkosten | B8: =-'4_Kosten'!B14 -> -56000 | C8: =-'4_Kosten'!C14 -> -114000 | D8: =-'4_Kosten'!D14 -> -174000 | E8: =-'4_Kosten'!E14 -> -216000 | F8: =-'4_Kosten'!F14 -> -244000
A9: EBITDA | B9: =B6+B8 -> -85028.495 | C9: =C6+C8 -> -67614.865 | D9: =D6+D8 -> 78388.674 | E9: =E6+E8 -> 689299.48 | F9: =F6+F8 -> 4055231.8
A10: EBITDA-Marge | B10: =IFERROR(B9/B4,0) -> -1.9403883 | C10: =IFERROR(C9/C4,0) -> -0.22550757 | D10: =IFERROR(D9/D4,0) -> 0.07165592 | E10: =IFERROR(E9/E4,0) -> 0.16394364 | F10: =IFERROR(F9/F4,0) -> 0.50566516
A12: KAPITALFLUSS & BREAKEVEN
A13: Kumulierter EBITDA | B13: =B9 -> -85028.495 | C13: =B13+C9 -> -152643.36 | D13: =C13+D9 -> -74254.685 | E13: =D13+E9 -> 615044.79 | F13: =E13+F9 -> 4670276.6
A14: Funding-Zufluss | B14: 1750000 | C14: 0 | D14: 5000000 | E14: 0 | F14: 0
A15: Funding (kumuliert) | B15: =B14 -> 1750000 | C15: =B15+C14 -> 1750000 | D15: =C15+D14 -> 6750000 | E15: =D15+E14 -> 6750000 | F15: =E15+F14 -> 6750000
A16: Cash-Bestand (Funding + kum. EBITDA) | B16: =B15+B13 -> 1664971.5 | C16: =C15+C13 -> 1597356.6 | D16: =D15+D13 -> 6675745.3 | E16: =E15+E13 -> 7365044.8 | F16: =F15+F13 -> 11420277
A18: BREAKEVEN-UMSATZ je Jahr (Fix / DB-Marge)
A19: Erforderlicher Umsatz für Breakeven | B19: =IFERROR(-B8/IFERROR(B6/B4,0),0) -> -84535.543 | C19: =IFERROR(-C8/IFERROR(C6/C4,0),0) -> 736897.5 | D19: =IFERROR(-D8/IFERROR(D6/D4,0),0) -> 754189.76 | E19: =IFERROR(-E8/IFERROR(E6/E4,0),0) -> 1003170.7 | F19: =IFERROR(-F8/IFERROR(F6/F4,0),0) -> 455146.93
A20: Tatsächlicher Umsatz | B20: =B4 -> 43820.35 | C20: =C4 -> 299834.12 | D20: =D4 -> 1093959.5 | E20: =E4 -> 4204490.5 | F20: =F4 -> 8019599
A21: Δ zu Breakeven | B21: =B4-B19 -> 128355.89 | C21: =C4-C19 -> -437063.37 | D21: =D4-D19 -> 339769.74 | E21: =E4-E19 -> 3201319.8 | F21: =F4-F19 -> 7564452.1
A23: Breakeven-Jahr (erstes Jahr mit positivem EBITDA): | B23: =IFERROR("Jahr "&MATCH(TRUE,B9:F9>0,0),"nach Jahr 5") -> nach Jahr 5

Sheet 7_Verlauf_Charts
A1: VERLAUFS-DATEN & DIAGRAMME
A3: Jahr | B3: Jahr 1 | C3: Jahr 2 | D3: Jahr 3 | E3: Jahr 4 | F3: Jahr 5
A4: Umsatz | B4: ='6_GuV_Breakeven'!B4 -> 43820.35 | C4: ='6_GuV_Breakeven'!C4 -> 299834.12 | D4: ='6_GuV_Breakeven'!D4 -> 1093959.5 | E4: ='6_GuV_Breakeven'!E4 -> 4204490.5 | F4: ='6_GuV_Breakeven'!F4 -> 8019599
A5: Fixkosten | B5: ='4_Kosten'!B14 -> 56000 | C5: ='4_Kosten'!C14 -> 114000 | D5: ='4_Kosten'!D14 -> 174000 | E5: ='4_Kosten'!E14 -> 216000 | F5: ='4_Kosten'!F14 -> 244000
A6: Variable Kosten | B6: ='5_Umsatz_Prognose'!B33 -> 72848.845 | C6: ='5_Umsatz_Prognose'!C33 -> 253448.99 | D6: ='5_Umsatz_Prognose'!D33 -> 841570.83 | E6: ='5_Umsatz_Prognose'!E33 -> 3299191 | F6: ='5_Umsatz_Prognose'!F33 -> 3720367.2
A7: Gesamtkosten | B7: ='4_Kosten'!B26 -> 128848.85 | C7: ='4_Kosten'!C26 -> 367448.99 | D7: ='4_Kosten'!D26 -> 1015570.8 | E7: ='4_Kosten'!E26 -> 3515191 | F7: ='4_Kosten'!F26 -> 3964367.2
A8: EBITDA | B8: ='6_GuV_Breakeven'!B9 -> -85028.495 | C8: ='6_GuV_Breakeven'!C9 -> -67614.865 | D8: ='6_GuV_Breakeven'!D9 -> 78388.674 | E8: ='6_GuV_Breakeven'!E9 -> 689299.48 | F8: ='6_GuV_Breakeven'!F9 -> 4055231.8
A9: Kumulierter EBITDA | B9: ='6_GuV_Breakeven'!B13 -> -85028.495 | C9: ='6_GuV_Breakeven'!C13 -> -152643.36 | D9: ='6_GuV_Breakeven'!D13 -> -74254.685 | E9: ='6_GuV_Breakeven'!E13 -> 615044.79 | F9: ='6_GuV_Breakeven'!F13 -> 4670276.6
A10: Cash-Bestand | B10: ='6_GuV_Breakeven'!B16 -> 1664971.5 | C10: ='6_GuV_Breakeven'!C16 -> 1597356.6 | D10: ='6_GuV_Breakeven'!D16 -> 6675745.3 | E10: ='6_GuV_Breakeven'!E16 -> 7365044.8 | F10: ='6_GuV_Breakeven'!F16 -> 11420277
A11: Breakeven-Umsatz | B11: ='6_GuV_Breakeven'!B19 -> -84535.543 | C11: ='6_GuV_Breakeven'!C19 -> 736897.5 | D11: ='6_GuV_Breakeven'!D19 -> 754189.76 | E11: ='6_GuV_Breakeven'!E19 -> 1003170.7 | F11: ='6_GuV_Breakeven'!F19 -> 455146.93

Sheet 8_Bewertung
A1: SKIPILY – Unternehmensbewertung (VC-Methode + Multiples)
A2: Verknüpft mit Tab 5 (Umsatz) & Tab 6 (EBITDA). Gelb = Inputs, grün = Querverweis.
A4: INPUT-ANNAHMEN (änderbar)
A5: Exit-Multiple auf Umsatz (J5) | B5: 4 | G5: Marktplatz/SaaS 3–6x; konservativ 4x
A6: Exit-Multiple auf EBITDA (J5) | B6: 12 | G6: Profit. SaaS 10–18x
A7: Gewichtung Umsatz-Methode | B7: 0.5 | G7: Rest = EBITDA-Methode
A8: Ziel-IRR Investor (Seed-Risiko) | B8: 0.5 | G8: früh: 40–60%
A9: Jahre bis Exit | B9: 5 | G9: Ende Planungshorizont
A10: Verwässerung bis Exit (Folgerunden) | B10: 0.55 | G10: Seed+Series A; Rest bleibt heutigen Anteilen
A12: KENNZAHLEN JAHR 5 (aus Modell)
A13: Umsatz Jahr 5 (€) | B13: ='5_Umsatz_Prognose'!F23 -> 8019599
A14: EBITDA Jahr 5 (€) | B14: ='6_GuV_Breakeven'!F9 -> 4055231.8
A16: EXIT-WERT (Jahr 5)
A17: Exit-Wert auf Umsatz-Basis (€) | B17: =B13*B5 -> 32078396
A18: Exit-Wert auf EBITDA-Basis (€) | B18: =B14*B6 -> 48662782
A19: Exit-Wert gewichtet (€) | B19: =B7*B17+(1-B7)*B18 -> 40370589
A21: VC-METHODE – Wert HEUTE
A22: Diskontfaktor (1+IRR)^Jahre | B22: =(1+B8)^B9 -> 7.59375
A23: Unternehmenswert heute – 100% (€) | B23: =B19/B22 -> 5316291.6
A24: Wert heutiger Anteile nach Verwässerung (€) | B24: =B23*(1-B10) -> 2392331.2
A26: SENSITIVITÄT – Unternehmenswert heute (100%, €)
A27: IRR ↓ / Exit-Umsatz-Multiple → | B27: 3 | C27: 4 | D27: 5 | E27: 6
A28: 0.45 | B28: =($B$13*B$27)/(1+$A28)^$B$9 -> 3753478.2 | C28: =($B$13*C$27)/(1+$A28)^$B$9 -> 5004637.6 | D28: =($B$13*D$27)/(1+$A28)^$B$9 -> 6255797 | E28: =($B$13*E$27)/(1+$A28)^$B$9 -> 7506956.4
A29: 0.5 | B29: =($B$13*B$27)/(1+$A29)^$B$9 -> 3168236.6 | C29: =($B$13*C$27)/(1+$A29)^$B$9 -> 4224315.5 | D29: =($B$13*D$27)/(1+$A29)^$B$9 -> 5280394.4 | E29: =($B$13*E$27)/(1+$A29)^$B$9 -> 6336473.3
A30: 0.55 | B30: =($B$13*B$27)/(1+$A30)^$B$9 -> 2689152.4 | C30: =($B$13*C$27)/(1+$A30)^$B$9 -> 3585536.5 | D30: =($B$13*D$27)/(1+$A30)^$B$9 -> 4481920.7 | E30: =($B$13*E$27)/(1+$A30)^$B$9 -> 5378304.8
A31: 0.6 | B31: =($B$13*B$27)/(1+$A31)^$B$9 -> 2294425.7 | C31: =($B$13*C$27)/(1+$A31)^$B$9 -> 3059234.2 | D31: =($B$13*D$27)/(1+$A31)^$B$9 -> 3824042.8 | E31: =($B$13*E$27)/(1+$A31)^$B$9 -> 4588851.4
A34: METHODENVERGLEICH → STARTWERT (pre-launch)
A35: Methode | B35: von (€) | C35: bis (€)
A36: Substanzwert (Reproduktion Produkt) | B36: 175000 | C36: 350000 | G36: Quelle: Modell J1 Produkt+Design ~265k
A37: Berkus / Scorecard (pre-launch) | B37: 1300000 | C37: 1700000 | G37: fertiges Produkt senkt Tech-Risiko
A38: DE-Pre-Seed Marktvergleich | B38: 800000 | C38: 1500000 | G38: fertiges Produkt, kein Umsatz
A39: VC-Methode (heute, 100%) | B39: =B23*0.8 -> 4253033.2 | C39: =B23*1.2 -> 6379549.9 | G39: ±20% um VC-Wert oben
A40: EMPFOHLENER STARTWERT (Pre-Money) | B40: 1200000 | C40: 1800000 | G40: Synthese: oberes Drittel DE-Pre-Seed wg. fertigem Produkt
A42: WERTKURVE BEI ZIELERREICHUNG
A43: Meilenstein | B43: Pre-Money von | C43: bis
A44: Heute (fertiges Produkt, pre-launch) | B44: 1200000 | C44: 1800000
A45: Ende J1 – Seed (erste zahlende Kunden) | B45: 3000000 | C45: 5000000
A46: J3 – Series A (1,85M Umsatz) | B46: 12000000 | C46: 20000000
A47: J5 – Exit-Fenster (8,68M Umsatz, 38% EBITDA) | B47: 35000000 | C47: 52000000
A49: HINWEIS: Bewertung ist keine Garantie. Werte hängen an den (gelben) Annahmen und an
...

Sheet 9_Beteiligung
A1: SKIPILY – Beteiligungsrechner (was kostet ein Anteil?)
A2: Investment = Pre-Money × Anteil ÷ (1−Anteil) · Post-Money = Pre-Money + Investment
A4: Angesetzte Pre-Money-Bewertung (€) | B4: 1500000 | E4: Mittelwert Startwert aus Tab 8 (1,2–1,8M) — änderbar
A6: A) Was kostet welcher Anteil?
A7: Anteil für Investor | B7: Investment (€) | C7: Post-Money (€) | D7: Gründer danach
A8: 0.05 | B8: =$B$4*A8/(1-A8) -> 78947.368 | C8: =$B$4+B8 -> 1578947.4 | D8: =1-A8 -> 0.95
A9: 0.1 | B9: =$B$4*A9/(1-A9) -> 166666.67 | C9: =$B$4+B9 -> 1666666.7 | D9: =1-A9 -> 0.9
A10: 0.15 | B10: =$B$4*A10/(1-A10) -> 264705.88 | C10: =$B$4+B10 -> 1764705.9 | D10: =1-A10 -> 0.85
A11: 0.2 | B11: =$B$4*A11/(1-A11) -> 375000 | C11: =$B$4+B11 -> 1875000 | D11: =1-A11 -> 0.8
A12: 0.25 | B12: =$B$4*A12/(1-A12) -> 500000 | C12: =$B$4+B12 -> 2000000 | D12: =1-A12 -> 0.75
A13: 0.3 | B13: =$B$4*A13/(1-A13) -> 642857.14 | C13: =$B$4+B13 -> 2142857.1 | D13: =1-A13 -> 0.7
A15: B) Was bekommt der Investor für X €?
A16: Investment (€) | B16: Anteil % | C16: Post-Money (€) | D16: Gründer danach
A17: 100000 | B17: =A17/($B$4+A17) -> 0.0625 | C17: =$B$4+A17 -> 1600000 | D17: =$B$4/($B$4+A17) -> 0.9375
A18: 250000 | B18: =A18/($B$4+A18) -> 0.14285714 | C18: =$B$4+A18 -> 1750000 | D18: =$B$4/($B$4+A18) -> 0.85714286
A19: 500000 | B19: =A19/($B$4+A19) -> 0.25 | C19: =$B$4+A19 -> 2000000 | D19: =$B$4/($B$4+A19) -> 0.75
A20: 750000 | B20: =A20/($B$4+A20) -> 0.33333333 | C20: =$B$4+A20 -> 2250000 | D20: =$B$4/($B$4+A20) -> 0.66666667
A21: 1000000 | B21: =A21/($B$4+A21) -> 0.4 | C21: =$B$4+A21 -> 2500000 | D21: =$B$4/($B$4+A21) -> 0.6
A22: 1500000 | B22: =A22/($B$4+A22) -> 0.5 | C22: =$B$4+A22 -> 3000000 | D22: =$B$4/($B$4+A22) -> 0.5
A24: REALITÄTS-CHECK: geplante Seed-Runde
A25: Seed-Volumen aus Tab 3 (€) | B25: ='3_Investment'!C20 -> 1500000 | E25: Quelle: Tab 3, Seed Round Q4 J1
A26: → Anteil bei dieser Pre-Money | B26: =B25/($B$4+B25) -> 0.5
A27: → Post-Money | B27: =$B$4+B25 -> 3000000
A29: FAUSTREGEL: Seed-Investoren wollen 10–25%. Mehr als ~25–30% Abgabe
A30: in einer frühen Runde schreckt spätere Investoren ab (zu wenig Gründer-Anteil).
A31: Lösung bei zu hoher Verwässerung: weniger raisen ODER höhere Pre-Money verhandeln.
